{
 "cells": [
  {
   "cell_type": "code",
   "execution_count": 6,
   "id": "ca046558",
   "metadata": {},
   "outputs": [
    {
     "name": "stdout",
     "output_type": "stream",
     "text": [
      "Collecting torch-geometric\n",
      "  Downloading torch_geometric-2.2.0.tar.gz (564 kB)\n",
      "Requirement already satisfied: tqdm in c:\\users\\stariz.pk\\anaconda3\\lib\\site-packages (from torch-geometric) (4.62.3)\n",
      "Requirement already satisfied: numpy in c:\\users\\stariz.pk\\anaconda3\\lib\\site-packages (from torch-geometric) (1.20.3)\n",
      "Requirement already satisfied: scipy in c:\\users\\stariz.pk\\anaconda3\\lib\\site-packages (from torch-geometric) (1.7.1)\n",
      "Requirement already satisfied: jinja2 in c:\\users\\stariz.pk\\anaconda3\\lib\\site-packages (from torch-geometric) (2.11.3)\n",
      "Requirement already satisfied: requests in c:\\users\\stariz.pk\\anaconda3\\lib\\site-packages (from torch-geometric) (2.26.0)\n",
      "Requirement already satisfied: pyparsing in c:\\users\\stariz.pk\\anaconda3\\lib\\site-packages (from torch-geometric) (3.0.4)\n",
      "Requirement already satisfied: scikit-learn in c:\\users\\stariz.pk\\anaconda3\\lib\\site-packages (from torch-geometric) (0.24.2)\n",
      "Requirement already satisfied: psutil>=5.8.0 in c:\\users\\stariz.pk\\anaconda3\\lib\\site-packages (from torch-geometric) (5.8.0)\n",
      "Requirement already satisfied: MarkupSafe>=0.23 in c:\\users\\stariz.pk\\anaconda3\\lib\\site-packages (from jinja2->torch-geometric) (1.1.1)\n",
      "Requirement already satisfied: idna<4,>=2.5 in c:\\users\\stariz.pk\\anaconda3\\lib\\site-packages (from requests->torch-geometric) (3.2)\n",
      "Requirement already satisfied: urllib3<1.27,>=1.21.1 in c:\\users\\stariz.pk\\anaconda3\\lib\\site-packages (from requests->torch-geometric) (1.26.7)\n",
      "Requirement already satisfied: certifi>=2017.4.17 in c:\\users\\stariz.pk\\anaconda3\\lib\\site-packages (from requests->torch-geometric) (2021.10.8)\n",
      "Requirement already satisfied: charset-normalizer~=2.0.0 in c:\\users\\stariz.pk\\anaconda3\\lib\\site-packages (from requests->torch-geometric) (2.0.4)\n",
      "Requirement already satisfied: joblib>=0.11 in c:\\users\\stariz.pk\\anaconda3\\lib\\site-packages (from scikit-learn->torch-geometric) (1.1.0)\n",
      "Requirement already satisfied: threadpoolctl>=2.0.0 in c:\\users\\stariz.pk\\anaconda3\\lib\\site-packages (from scikit-learn->torch-geometric) (2.2.0)\n",
      "Requirement already satisfied: colorama in c:\\users\\stariz.pk\\anaconda3\\lib\\site-packages (from tqdm->torch-geometric) (0.4.4)\n",
      "Building wheels for collected packages: torch-geometric\n",
      "  Building wheel for torch-geometric (setup.py): started\n",
      "  Building wheel for torch-geometric (setup.py): finished with status 'done'\n",
      "  Created wheel for torch-geometric: filename=torch_geometric-2.2.0-py3-none-any.whl size=773302 sha256=72dc524783913feb76de660c6cf773d010a64ed037c5708731b3978f0a1450e2\n",
      "  Stored in directory: c:\\users\\stariz.pk\\appdata\\local\\pip\\cache\\wheels\\31\\b2\\8c\\9b4bb72a4384eabd1ffeab2b7ead692c9165e35711f8a9dc72\n",
      "Successfully built torch-geometric\n",
      "Installing collected packages: torch-geometric\n",
      "Successfully installed torch-geometric-2.2.0\n",
      "Found existing installation: torch 1.12.1"
     ]
    },
    {
     "name": "stderr",
     "output_type": "stream",
     "text": [
      "ERROR: Exception:\n",
      "Traceback (most recent call last):\n",
      "  File \"C:\\Users\\STARIZ.PK\\anaconda3\\lib\\site-packages\\pip\\_internal\\cli\\base_command.py\", line 173, in _main\n",
      "    status = self.run(options, args)\n",
      "  File \"C:\\Users\\STARIZ.PK\\anaconda3\\lib\\site-packages\\pip\\_internal\\commands\\uninstall.py\", line 97, in run\n",
      "    uninstall_pathset.commit()\n",
      "  File \"C:\\Users\\STARIZ.PK\\anaconda3\\lib\\site-packages\\pip\\_internal\\req\\req_uninstall.py\", line 436, in commit\n",
      "    self._moved_paths.commit()\n",
      "  File \"C:\\Users\\STARIZ.PK\\anaconda3\\lib\\site-packages\\pip\\_internal\\req\\req_uninstall.py\", line 287, in commit\n",
      "    save_dir.cleanup()\n",
      "  File \"C:\\Users\\STARIZ.PK\\anaconda3\\lib\\site-packages\\pip\\_internal\\utils\\temp_dir.py\", line 184, in cleanup\n",
      "    rmtree(self._path)\n",
      "  File \"C:\\Users\\STARIZ.PK\\anaconda3\\lib\\site-packages\\pip\\_vendor\\tenacity\\__init__.py\", line 326, in wrapped_f\n",
      "    return self(f, *args, **kw)\n",
      "  File \"C:\\Users\\STARIZ.PK\\anaconda3\\lib\\site-packages\\pip\\_vendor\\tenacity\\__init__.py\", line 406, in __call__\n",
      "    do = self.iter(retry_state=retry_state)\n",
      "  File \"C:\\Users\\STARIZ.PK\\anaconda3\\lib\\site-packages\\pip\\_vendor\\tenacity\\__init__.py\", line 362, in iter\n",
      "    raise retry_exc.reraise()\n",
      "  File \"C:\\Users\\STARIZ.PK\\anaconda3\\lib\\site-packages\\pip\\_vendor\\tenacity\\__init__.py\", line 195, in reraise\n",
      "    raise self.last_attempt.result()\n",
      "  File \"C:\\Users\\STARIZ.PK\\anaconda3\\lib\\concurrent\\futures\\_base.py\", line 438, in result\n",
      "    return self.__get_result()\n",
      "  File \"C:\\Users\\STARIZ.PK\\anaconda3\\lib\\concurrent\\futures\\_base.py\", line 390, in __get_result\n",
      "    raise self._exception\n",
      "  File \"C:\\Users\\STARIZ.PK\\anaconda3\\lib\\site-packages\\pip\\_vendor\\tenacity\\__init__.py\", line 409, in __call__\n",
      "    result = fn(*args, **kwargs)\n",
      "  File \"C:\\Users\\STARIZ.PK\\anaconda3\\lib\\site-packages\\pip\\_internal\\utils\\misc.py\", line 135, in rmtree\n",
      "    shutil.rmtree(dir, ignore_errors=ignore_errors, onerror=rmtree_errorhandler)\n",
      "  File \"C:\\Users\\STARIZ.PK\\anaconda3\\lib\\shutil.py\", line 748, in rmtree\n",
      "    return _rmtree_unsafe(path, onerror)\n",
      "  File \"C:\\Users\\STARIZ.PK\\anaconda3\\lib\\shutil.py\", line 621, in _rmtree_unsafe\n",
      "    _rmtree_unsafe(fullname, onerror)\n",
      "  File \"C:\\Users\\STARIZ.PK\\anaconda3\\lib\\shutil.py\", line 626, in _rmtree_unsafe\n"
     ]
    },
    {
     "name": "stdout",
     "output_type": "stream",
     "text": [
      "\n",
      "Uninstalling torch-1.12.1:\n",
      "  Successfully uninstalled torch-1.12.1\n"
     ]
    },
    {
     "name": "stderr",
     "output_type": "stream",
     "text": [
      "    onerror(os.unlink, fullname, sys.exc_info())\n",
      "  File \"C:\\Users\\STARIZ.PK\\anaconda3\\lib\\shutil.py\", line 624, in _rmtree_unsafe\n",
      "    os.unlink(fullname)\n",
      "PermissionError: [WinError 5] Access is denied: 'C:\\\\Users\\\\STARIZ.PK\\\\anaconda3\\\\Lib\\\\site-packages\\\\~orch\\\\lib\\\\asmjit.dll'\n"
     ]
    },
    {
     "name": "stdout",
     "output_type": "stream",
     "text": [
      "Found existing installation: torchvision 0.13.1\n",
      "Uninstalling torchvision-0.13.1:\n",
      "  Successfully uninstalled torchvision-0.13.1\n"
     ]
    },
    {
     "name": "stderr",
     "output_type": "stream",
     "text": [
      "WARNING: Retrying (Retry(total=4, connect=None, read=None, redirect=None, status=None)) after connection broken by 'ReadTimeoutError(\"HTTPSConnectionPool(host='pypi.org', port=443): Read timed out. (read timeout=15)\")': /simple/torch/\n",
      "WARNING: Retrying (Retry(total=3, connect=None, read=None, redirect=None, status=None)) after connection broken by 'ProtocolError('Connection aborted.', ConnectionResetError(10054, 'An existing connection was forcibly closed by the remote host', None, 10054, None))': /simple/torch/\n",
      "WARNING: Retrying (Retry(total=2, connect=None, read=None, redirect=None, status=None)) after connection broken by 'ReadTimeoutError(\"HTTPSConnectionPool(host='pypi.org', port=443): Read timed out. (read timeout=15)\")': /simple/torch/\n",
      "ERROR: Could not find a version that satisfies the requirement torch==1.6.0 (from versions: 1.7.1, 1.8.0, 1.8.1, 1.9.0, 1.9.1, 1.10.0, 1.10.1, 1.10.2, 1.11.0, 1.12.0, 1.12.1, 1.13.0, 1.13.1)\n",
      "ERROR: No matching distribution found for torch==1.6.0\n",
      "ERROR: Could not find a version that satisfies the requirement torchvision==0.7.0 (from versions: 0.1.6, 0.1.7, 0.1.8, 0.1.9, 0.2.0, 0.2.1, 0.2.2, 0.2.2.post2, 0.2.2.post3, 0.9.0, 0.9.1, 0.10.0, 0.10.1, 0.11.0, 0.11.1, 0.11.2, 0.11.3, 0.12.0, 0.13.0, 0.13.1, 0.14.0, 0.14.1)\n",
      "ERROR: No matching distribution found for torchvision==0.7.0\n",
      "Traceback (most recent call last):\n",
      "  File \"<string>\", line 1, in <module>\n",
      "ModuleNotFoundError: No module named 'torch'\n",
      "Traceback (most recent call last):\n",
      "  File \"<string>\", line 1, in <module>\n",
      "ModuleNotFoundError: No module named 'torch'\n"
     ]
    },
    {
     "name": "stdout",
     "output_type": "stream",
     "text": [
      "Python 3.9.7\n"
     ]
    },
    {
     "name": "stderr",
     "output_type": "stream",
     "text": [
      "'nvidia-smi' is not recognized as an internal or external command,\n",
      "operable program or batch file.\n"
     ]
    }
   ],
   "source": [
    "import torch\n",
    "if torch.__version__ != '1.6.0':\n",
    "  !pip uninstall torch -y\n",
    "  !pip uninstall torchvision -y\n",
    "  !pip install torch==1.6.0\n",
    "  !pip install torchvision==0.7.0\n",
    "\n",
    "# Check pytorch version and make sure you use a GPU Kernel\n",
    "!python -c \"import torch; print(torch.__version__)\"\n",
    "!python -c \"import torch; print(torch.version.cuda)\"\n",
    "!python --version\n",
    "!nvidia-smi"
   ]
  },
  {
   "cell_type": "code",
   "execution_count": 7,
   "id": "8820b2cb",
   "metadata": {},
   "outputs": [
    {
     "name": "stdout",
     "output_type": "stream",
     "text": [
      "Looking in links: https://pytorch-geometric.com/whl/torch-1.12.1+cpu.html\n",
      "Collecting torch-scatter\n",
      "  Downloading https://data.pyg.org/whl/torch-1.12.0%2Bcpu/torch_scatter-2.1.0%2Bpt112cpu-cp39-cp39-win_amd64.whl (329 kB)\n",
      "Installing collected packages: torch-scatter\n",
      "Successfully installed torch-scatter-2.1.0+pt112cpu\n"
     ]
    },
    {
     "name": "stderr",
     "output_type": "stream",
     "text": [
      "  WARNING: Retrying (Retry(total=4, connect=None, read=None, redirect=None, status=None)) after connection broken by 'ReadTimeoutError(\"HTTPSConnectionPool(host='data.pyg.org', port=443): Read timed out. (read timeout=15)\")': /whl/torch-1.12.0%2Bcpu/torch_scatter-2.1.0%2Bpt112cpu-cp39-cp39-win_amd64.whl\n"
     ]
    },
    {
     "name": "stdout",
     "output_type": "stream",
     "text": [
      "Looking in links: https://pytorch-geometric.com/whl/torch-1.12.1+cpu.html\n"
     ]
    },
    {
     "name": "stderr",
     "output_type": "stream",
     "text": [
      "WARNING: Retrying (Retry(total=4, connect=None, read=None, redirect=None, status=None)) after connection broken by 'ConnectTimeoutError(<pip._vendor.urllib3.connection.HTTPSConnection object at 0x00000191E5D90A30>, 'Connection to pytorch-geometric.com timed out. (connect timeout=15)')': /whl/torch-1.12.1+cpu.html\n",
      "WARNING: Retrying (Retry(total=3, connect=None, read=None, redirect=None, status=None)) after connection broken by 'NewConnectionError('<pip._vendor.urllib3.connection.HTTPSConnection object at 0x00000191E5D998E0>: Failed to establish a new connection: [WinError 10051] A socket operation was attempted to an unreachable network')': /whl/torch-1.12.1+cpu.html\n",
      "WARNING: Retrying (Retry(total=2, connect=None, read=None, redirect=None, status=None)) after connection broken by 'NewConnectionError('<pip._vendor.urllib3.connection.HTTPSConnection object at 0x00000191E5D990D0>: Failed to establish a new connection: [Errno 11001] getaddrinfo failed')': /whl/torch-1.12.1+cpu.html\n",
      "WARNING: Retrying (Retry(total=1, connect=None, read=None, redirect=None, status=None)) after connection broken by 'NewConnectionError('<pip._vendor.urllib3.connection.HTTPSConnection object at 0x00000191E5D99A00>: Failed to establish a new connection: [Errno 11001] getaddrinfo failed')': /whl/torch-1.12.1+cpu.html\n",
      "WARNING: Retrying (Retry(total=0, connect=None, read=None, redirect=None, status=None)) after connection broken by 'NewConnectionError('<pip._vendor.urllib3.connection.HTTPSConnection object at 0x00000191E5D99BB0>: Failed to establish a new connection: [Errno 11001] getaddrinfo failed')': /whl/torch-1.12.1+cpu.html\n",
      "ERROR: Could not find a version that satisfies the requirement torch-sparse (from versions: none)\n",
      "ERROR: No matching distribution found for torch-sparse\n"
     ]
    },
    {
     "name": "stdout",
     "output_type": "stream",
     "text": [
      "Looking in links: https://pytorch-geometric.com/whl/torch-1.12.1+cpu.html\n",
      "Collecting torch-cluster\n",
      "  Downloading https://data.pyg.org/whl/torch-1.12.0%2Bcpu/torch_cluster-1.6.0%2Bpt112cpu-cp39-cp39-win_amd64.whl (479 kB)\n"
     ]
    },
    {
     "name": "stderr",
     "output_type": "stream",
     "text": [
      "WARNING: Retrying (Retry(total=4, connect=None, read=None, redirect=None, status=None)) after connection broken by 'NewConnectionError('<pip._vendor.urllib3.connection.HTTPSConnection object at 0x0000029AC3E30A30>: Failed to establish a new connection: [Errno 11001] getaddrinfo failed')': /whl/torch-1.12.1+cpu.html\n",
      "WARNING: Retrying (Retry(total=3, connect=None, read=None, redirect=None, status=None)) after connection broken by 'NewConnectionError('<pip._vendor.urllib3.connection.HTTPSConnection object at 0x0000029AC3E39250>: Failed to establish a new connection: [Errno 11001] getaddrinfo failed')': /whl/torch-1.12.1+cpu.html\n",
      "WARNING: Retrying (Retry(total=2, connect=None, read=None, redirect=None, status=None)) after connection broken by 'ReadTimeoutError(\"HTTPSConnectionPool(host='pytorch-geometric.com', port=443): Read timed out. (read timeout=15)\")': /whl/torch-1.12.1+cpu.html\n",
      "WARNING: Retrying (Retry(total=1, connect=None, read=None, redirect=None, status=None)) after connection broken by 'NewConnectionError('<pip._vendor.urllib3.connection.HTTPSConnection object at 0x0000029AC3E39A60>: Failed to establish a new connection: [Errno 11001] getaddrinfo failed')': /whl/torch-1.12.1+cpu.html\n",
      "WARNING: Retrying (Retry(total=0, connect=None, read=None, redirect=None, status=None)) after connection broken by 'NewConnectionError('<pip._vendor.urllib3.connection.HTTPSConnection object at 0x0000029AC3E39C10>: Failed to establish a new connection: [Errno 11001] getaddrinfo failed')': /whl/torch-1.12.1+cpu.html\n",
      "  WARNING: Retrying (Retry(total=4, connect=None, read=None, redirect=None, status=None)) after connection broken by 'ReadTimeoutError(\"HTTPSConnectionPool(host='data.pyg.org', port=443): Read timed out. (read timeout=15)\")': /whl/torch-1.12.0%2Bcpu/torch_cluster-1.6.0%2Bpt112cpu-cp39-cp39-win_amd64.whl\n",
      "  WARNING: Retrying (Retry(total=3, connect=None, read=None, redirect=None, status=None)) after connection broken by 'NewConnectionError('<pip._vendor.urllib3.connection.HTTPSConnection object at 0x0000029AC3EEAAC0>: Failed to establish a new connection: [Errno 11001] getaddrinfo failed')': /whl/torch-1.12.0%2Bcpu/torch_cluster-1.6.0%2Bpt112cpu-cp39-cp39-win_amd64.whl\n",
      "ERROR: Exception:\n",
      "Traceback (most recent call last):\n",
      "  File \"C:\\Users\\STARIZ.PK\\anaconda3\\lib\\site-packages\\pip\\_vendor\\urllib3\\response.py\", line 438, in _error_catcher\n",
      "    yield\n",
      "  File \"C:\\Users\\STARIZ.PK\\anaconda3\\lib\\site-packages\\pip\\_vendor\\urllib3\\response.py\", line 519, in read\n",
      "    data = self._fp.read(amt) if not fp_closed else b\"\"\n",
      "  File \"C:\\Users\\STARIZ.PK\\anaconda3\\lib\\site-packages\\pip\\_vendor\\cachecontrol\\filewrapper.py\", line 62, in read\n",
      "    data = self.__fp.read(amt)\n",
      "  File \"C:\\Users\\STARIZ.PK\\anaconda3\\lib\\http\\client.py\", line 462, in read\n",
      "    n = self.readinto(b)\n",
      "  File \"C:\\Users\\STARIZ.PK\\anaconda3\\lib\\http\\client.py\", line 506, in readinto\n",
      "    n = self.fp.readinto(b)\n",
      "  File \"C:\\Users\\STARIZ.PK\\anaconda3\\lib\\socket.py\", line 704, in readinto\n",
      "    return self._sock.recv_into(b)\n",
      "  File \"C:\\Users\\STARIZ.PK\\anaconda3\\lib\\ssl.py\", line 1241, in recv_into\n",
      "    return self.read(nbytes, buffer)\n",
      "  File \"C:\\Users\\STARIZ.PK\\anaconda3\\lib\\ssl.py\", line 1099, in read\n",
      "    return self._sslobj.read(len, buffer)\n",
      "socket.timeout: The read operation timed out\n",
      "\n",
      "During handling of the above exception, another exception occurred:\n",
      "\n",
      "Traceback (most recent call last):\n",
      "  File \"C:\\Users\\STARIZ.PK\\anaconda3\\lib\\site-packages\\pip\\_internal\\cli\\base_command.py\", line 173, in _main\n",
      "    status = self.run(options, args)\n",
      "  File \"C:\\Users\\STARIZ.PK\\anaconda3\\lib\\site-packages\\pip\\_internal\\cli\\req_command.py\", line 203, in wrapper\n",
      "    return func(self, options, args)\n",
      "  File \"C:\\Users\\STARIZ.PK\\anaconda3\\lib\\site-packages\\pip\\_internal\\commands\\install.py\", line 315, in run\n",
      "    requirement_set = resolver.resolve(\n",
      "  File \"C:\\Users\\STARIZ.PK\\anaconda3\\lib\\site-packages\\pip\\_internal\\resolution\\resolvelib\\resolver.py\", line 94, in resolve\n",
      "    result = self._result = resolver.resolve(\n",
      "  File \"C:\\Users\\STARIZ.PK\\anaconda3\\lib\\site-packages\\pip\\_vendor\\resolvelib\\resolvers.py\", line 472, in resolve\n",
      "    state = resolution.resolve(requirements, max_rounds=max_rounds)\n",
      "  File \"C:\\Users\\STARIZ.PK\\anaconda3\\lib\\site-packages\\pip\\_vendor\\resolvelib\\resolvers.py\", line 341, in resolve\n",
      "    self._add_to_criteria(self.state.criteria, r, parent=None)\n",
      "  File \"C:\\Users\\STARIZ.PK\\anaconda3\\lib\\site-packages\\pip\\_vendor\\resolvelib\\resolvers.py\", line 172, in _add_to_criteria\n",
      "    if not criterion.candidates:\n",
      "  File \"C:\\Users\\STARIZ.PK\\anaconda3\\lib\\site-packages\\pip\\_vendor\\resolvelib\\structs.py\", line 151, in __bool__\n",
      "    return bool(self._sequence)\n",
      "  File \"C:\\Users\\STARIZ.PK\\anaconda3\\lib\\site-packages\\pip\\_internal\\resolution\\resolvelib\\found_candidates.py\", line 140, in __bool__\n",
      "    return any(self)\n",
      "  File \"C:\\Users\\STARIZ.PK\\anaconda3\\lib\\site-packages\\pip\\_internal\\resolution\\resolvelib\\found_candidates.py\", line 128, in <genexpr>\n",
      "    return (c for c in iterator if id(c) not in self._incompatible_ids)\n",
      "  File \"C:\\Users\\STARIZ.PK\\anaconda3\\lib\\site-packages\\pip\\_internal\\resolution\\resolvelib\\found_candidates.py\", line 32, in _iter_built\n",
      "    candidate = func()\n",
      "  File \"C:\\Users\\STARIZ.PK\\anaconda3\\lib\\site-packages\\pip\\_internal\\resolution\\resolvelib\\factory.py\", line 204, in _make_candidate_from_link\n",
      "    self._link_candidate_cache[link] = LinkCandidate(\n",
      "  File \"C:\\Users\\STARIZ.PK\\anaconda3\\lib\\site-packages\\pip\\_internal\\resolution\\resolvelib\\candidates.py\", line 295, in __init__\n",
      "    super().__init__(\n",
      "  File \"C:\\Users\\STARIZ.PK\\anaconda3\\lib\\site-packages\\pip\\_internal\\resolution\\resolvelib\\candidates.py\", line 156, in __init__\n",
      "    self.dist = self._prepare()\n",
      "  File \"C:\\Users\\STARIZ.PK\\anaconda3\\lib\\site-packages\\pip\\_internal\\resolution\\resolvelib\\candidates.py\", line 227, in _prepare\n",
      "    dist = self._prepare_distribution()\n",
      "  File \"C:\\Users\\STARIZ.PK\\anaconda3\\lib\\site-packages\\pip\\_internal\\resolution\\resolvelib\\candidates.py\", line 305, in _prepare_distribution\n",
      "    return self._factory.preparer.prepare_linked_requirement(\n",
      "  File \"C:\\Users\\STARIZ.PK\\anaconda3\\lib\\site-packages\\pip\\_internal\\operations\\prepare.py\", line 508, in prepare_linked_requirement\n",
      "    return self._prepare_linked_requirement(req, parallel_builds)\n",
      "  File \"C:\\Users\\STARIZ.PK\\anaconda3\\lib\\site-packages\\pip\\_internal\\operations\\prepare.py\", line 550, in _prepare_linked_requirement\n",
      "    local_file = unpack_url(\n",
      "  File \"C:\\Users\\STARIZ.PK\\anaconda3\\lib\\site-packages\\pip\\_internal\\operations\\prepare.py\", line 239, in unpack_url\n",
      "    file = get_http_url(\n",
      "  File \"C:\\Users\\STARIZ.PK\\anaconda3\\lib\\site-packages\\pip\\_internal\\operations\\prepare.py\", line 102, in get_http_url\n",
      "    from_path, content_type = download(link, temp_dir.path)\n",
      "  File \"C:\\Users\\STARIZ.PK\\anaconda3\\lib\\site-packages\\pip\\_internal\\network\\download.py\", line 145, in __call__\n",
      "    for chunk in chunks:\n",
      "  File \"C:\\Users\\STARIZ.PK\\anaconda3\\lib\\site-packages\\pip\\_internal\\cli\\progress_bars.py\", line 144, in iter\n",
      "    for x in it:\n",
      "  File \"C:\\Users\\STARIZ.PK\\anaconda3\\lib\\site-packages\\pip\\_internal\\network\\utils.py\", line 63, in response_chunks\n",
      "    for chunk in response.raw.stream(\n",
      "  File \"C:\\Users\\STARIZ.PK\\anaconda3\\lib\\site-packages\\pip\\_vendor\\urllib3\\response.py\", line 576, in stream\n",
      "    data = self.read(amt=amt, decode_content=decode_content)\n",
      "  File \"C:\\Users\\STARIZ.PK\\anaconda3\\lib\\site-packages\\pip\\_vendor\\urllib3\\response.py\", line 541, in read\n",
      "    raise IncompleteRead(self._fp_bytes_read, self.length_remaining)\n",
      "  File \"C:\\Users\\STARIZ.PK\\anaconda3\\lib\\contextlib.py\", line 137, in __exit__\n",
      "    self.gen.throw(typ, value, traceback)\n",
      "  File \"C:\\Users\\STARIZ.PK\\anaconda3\\lib\\site-packages\\pip\\_vendor\\urllib3\\response.py\", line 443, in _error_catcher\n",
      "    raise ReadTimeoutError(self._pool, None, \"Read timed out.\")\n",
      "pip._vendor.urllib3.exceptions.ReadTimeoutError: HTTPSConnectionPool(host='data.pyg.org', port=443): Read timed out.\n"
     ]
    },
    {
     "name": "stdout",
     "output_type": "stream",
     "text": [
      "Looking in links: https://pytorch-geometric.com/whl/torch-1.12.1+cpu.html\n",
      "Collecting torch-spline-conv\n",
      "  Downloading https://data.pyg.org/whl/torch-1.12.0%2Bcpu/torch_spline_conv-1.2.1%2Bpt112cpu-cp39-cp39-win_amd64.whl (169 kB)\n"
     ]
    },
    {
     "name": "stderr",
     "output_type": "stream",
     "text": [
      "WARNING: Retrying (Retry(total=4, connect=None, read=None, redirect=None, status=None)) after connection broken by 'ReadTimeoutError(\"HTTPSConnectionPool(host='pytorch-geometric.com', port=443): Read timed out. (read timeout=15)\")': /whl/torch-1.12.1+cpu.html\n",
      "WARNING: Retrying (Retry(total=3, connect=None, read=None, redirect=None, status=None)) after connection broken by 'NewConnectionError('<pip._vendor.urllib3.connection.HTTPSConnection object at 0x000002CDF56BA1C0>: Failed to establish a new connection: [Errno 11001] getaddrinfo failed')': /whl/torch-1.12.1+cpu.html\n",
      "WARNING: Retrying (Retry(total=2, connect=None, read=None, redirect=None, status=None)) after connection broken by 'NewConnectionError('<pip._vendor.urllib3.connection.HTTPSConnection object at 0x000002CDF56BA100>: Failed to establish a new connection: [Errno 11001] getaddrinfo failed')': /whl/torch-1.12.1+cpu.html\n",
      "ERROR: Exception:\n",
      "Traceback (most recent call last):\n",
      "  File \"C:\\Users\\STARIZ.PK\\anaconda3\\lib\\site-packages\\pip\\_vendor\\urllib3\\response.py\", line 438, in _error_catcher\n",
      "    yield\n",
      "  File \"C:\\Users\\STARIZ.PK\\anaconda3\\lib\\site-packages\\pip\\_vendor\\urllib3\\response.py\", line 519, in read\n",
      "    data = self._fp.read(amt) if not fp_closed else b\"\"\n",
      "  File \"C:\\Users\\STARIZ.PK\\anaconda3\\lib\\site-packages\\pip\\_vendor\\cachecontrol\\filewrapper.py\", line 62, in read\n",
      "    data = self.__fp.read(amt)\n",
      "  File \"C:\\Users\\STARIZ.PK\\anaconda3\\lib\\http\\client.py\", line 462, in read\n",
      "    n = self.readinto(b)\n",
      "  File \"C:\\Users\\STARIZ.PK\\anaconda3\\lib\\http\\client.py\", line 506, in readinto\n",
      "    n = self.fp.readinto(b)\n",
      "  File \"C:\\Users\\STARIZ.PK\\anaconda3\\lib\\socket.py\", line 704, in readinto\n",
      "    return self._sock.recv_into(b)\n",
      "  File \"C:\\Users\\STARIZ.PK\\anaconda3\\lib\\ssl.py\", line 1241, in recv_into\n",
      "    return self.read(nbytes, buffer)\n",
      "  File \"C:\\Users\\STARIZ.PK\\anaconda3\\lib\\ssl.py\", line 1099, in read\n",
      "    return self._sslobj.read(len, buffer)\n",
      "socket.timeout: The read operation timed out\n",
      "\n",
      "During handling of the above exception, another exception occurred:\n",
      "\n",
      "Traceback (most recent call last):\n",
      "  File \"C:\\Users\\STARIZ.PK\\anaconda3\\lib\\site-packages\\pip\\_internal\\cli\\base_command.py\", line 173, in _main\n",
      "    status = self.run(options, args)\n",
      "  File \"C:\\Users\\STARIZ.PK\\anaconda3\\lib\\site-packages\\pip\\_internal\\cli\\req_command.py\", line 203, in wrapper\n",
      "    return func(self, options, args)\n",
      "  File \"C:\\Users\\STARIZ.PK\\anaconda3\\lib\\site-packages\\pip\\_internal\\commands\\install.py\", line 315, in run\n",
      "    requirement_set = resolver.resolve(\n",
      "  File \"C:\\Users\\STARIZ.PK\\anaconda3\\lib\\site-packages\\pip\\_internal\\resolution\\resolvelib\\resolver.py\", line 94, in resolve\n",
      "    result = self._result = resolver.resolve(\n",
      "  File \"C:\\Users\\STARIZ.PK\\anaconda3\\lib\\site-packages\\pip\\_vendor\\resolvelib\\resolvers.py\", line 472, in resolve\n",
      "    state = resolution.resolve(requirements, max_rounds=max_rounds)\n",
      "  File \"C:\\Users\\STARIZ.PK\\anaconda3\\lib\\site-packages\\pip\\_vendor\\resolvelib\\resolvers.py\", line 341, in resolve\n",
      "    self._add_to_criteria(self.state.criteria, r, parent=None)\n",
      "  File \"C:\\Users\\STARIZ.PK\\anaconda3\\lib\\site-packages\\pip\\_vendor\\resolvelib\\resolvers.py\", line 172, in _add_to_criteria\n",
      "    if not criterion.candidates:\n",
      "  File \"C:\\Users\\STARIZ.PK\\anaconda3\\lib\\site-packages\\pip\\_vendor\\resolvelib\\structs.py\", line 151, in __bool__\n",
      "    return bool(self._sequence)\n",
      "  File \"C:\\Users\\STARIZ.PK\\anaconda3\\lib\\site-packages\\pip\\_internal\\resolution\\resolvelib\\found_candidates.py\", line 140, in __bool__\n",
      "    return any(self)\n",
      "  File \"C:\\Users\\STARIZ.PK\\anaconda3\\lib\\site-packages\\pip\\_internal\\resolution\\resolvelib\\found_candidates.py\", line 128, in <genexpr>\n",
      "    return (c for c in iterator if id(c) not in self._incompatible_ids)\n",
      "  File \"C:\\Users\\STARIZ.PK\\anaconda3\\lib\\site-packages\\pip\\_internal\\resolution\\resolvelib\\found_candidates.py\", line 32, in _iter_built\n",
      "    candidate = func()\n",
      "  File \"C:\\Users\\STARIZ.PK\\anaconda3\\lib\\site-packages\\pip\\_internal\\resolution\\resolvelib\\factory.py\", line 204, in _make_candidate_from_link\n",
      "    self._link_candidate_cache[link] = LinkCandidate(\n",
      "  File \"C:\\Users\\STARIZ.PK\\anaconda3\\lib\\site-packages\\pip\\_internal\\resolution\\resolvelib\\candidates.py\", line 295, in __init__\n",
      "    super().__init__(\n",
      "  File \"C:\\Users\\STARIZ.PK\\anaconda3\\lib\\site-packages\\pip\\_internal\\resolution\\resolvelib\\candidates.py\", line 156, in __init__\n",
      "    self.dist = self._prepare()\n",
      "  File \"C:\\Users\\STARIZ.PK\\anaconda3\\lib\\site-packages\\pip\\_internal\\resolution\\resolvelib\\candidates.py\", line 227, in _prepare\n",
      "    dist = self._prepare_distribution()\n",
      "  File \"C:\\Users\\STARIZ.PK\\anaconda3\\lib\\site-packages\\pip\\_internal\\resolution\\resolvelib\\candidates.py\", line 305, in _prepare_distribution\n",
      "    return self._factory.preparer.prepare_linked_requirement(\n",
      "  File \"C:\\Users\\STARIZ.PK\\anaconda3\\lib\\site-packages\\pip\\_internal\\operations\\prepare.py\", line 508, in prepare_linked_requirement\n",
      "    return self._prepare_linked_requirement(req, parallel_builds)\n",
      "  File \"C:\\Users\\STARIZ.PK\\anaconda3\\lib\\site-packages\\pip\\_internal\\operations\\prepare.py\", line 550, in _prepare_linked_requirement\n",
      "    local_file = unpack_url(\n",
      "  File \"C:\\Users\\STARIZ.PK\\anaconda3\\lib\\site-packages\\pip\\_internal\\operations\\prepare.py\", line 239, in unpack_url\n",
      "    file = get_http_url(\n",
      "  File \"C:\\Users\\STARIZ.PK\\anaconda3\\lib\\site-packages\\pip\\_internal\\operations\\prepare.py\", line 102, in get_http_url\n",
      "    from_path, content_type = download(link, temp_dir.path)\n",
      "  File \"C:\\Users\\STARIZ.PK\\anaconda3\\lib\\site-packages\\pip\\_internal\\network\\download.py\", line 145, in __call__\n",
      "    for chunk in chunks:\n",
      "  File \"C:\\Users\\STARIZ.PK\\anaconda3\\lib\\site-packages\\pip\\_internal\\cli\\progress_bars.py\", line 144, in iter\n",
      "    for x in it:\n",
      "  File \"C:\\Users\\STARIZ.PK\\anaconda3\\lib\\site-packages\\pip\\_internal\\network\\utils.py\", line 63, in response_chunks\n",
      "    for chunk in response.raw.stream(\n",
      "  File \"C:\\Users\\STARIZ.PK\\anaconda3\\lib\\site-packages\\pip\\_vendor\\urllib3\\response.py\", line 576, in stream\n",
      "    data = self.read(amt=amt, decode_content=decode_content)\n",
      "  File \"C:\\Users\\STARIZ.PK\\anaconda3\\lib\\site-packages\\pip\\_vendor\\urllib3\\response.py\", line 541, in read\n",
      "    raise IncompleteRead(self._fp_bytes_read, self.length_remaining)\n",
      "  File \"C:\\Users\\STARIZ.PK\\anaconda3\\lib\\contextlib.py\", line 137, in __exit__\n",
      "    self.gen.throw(typ, value, traceback)\n",
      "  File \"C:\\Users\\STARIZ.PK\\anaconda3\\lib\\site-packages\\pip\\_vendor\\urllib3\\response.py\", line 443, in _error_catcher\n",
      "    raise ReadTimeoutError(self._pool, None, \"Read timed out.\")\n",
      "pip._vendor.urllib3.exceptions.ReadTimeoutError: HTTPSConnectionPool(host='data.pyg.org', port=443): Read timed out.\n"
     ]
    },
    {
     "name": "stdout",
     "output_type": "stream",
     "text": [
      "Requirement already satisfied: torch-geometric in c:\\users\\stariz.pk\\anaconda3\\lib\\site-packages (2.2.0)\n",
      "Requirement already satisfied: requests in c:\\users\\stariz.pk\\anaconda3\\lib\\site-packages (from torch-geometric) (2.26.0)\n",
      "Requirement already satisfied: psutil>=5.8.0 in c:\\users\\stariz.pk\\anaconda3\\lib\\site-packages (from torch-geometric) (5.8.0)\n",
      "Requirement already satisfied: pyparsing in c:\\users\\stariz.pk\\anaconda3\\lib\\site-packages (from torch-geometric) (3.0.4)\n",
      "Requirement already satisfied: jinja2 in c:\\users\\stariz.pk\\anaconda3\\lib\\site-packages (from torch-geometric) (2.11.3)\n",
      "Requirement already satisfied: numpy in c:\\users\\stariz.pk\\anaconda3\\lib\\site-packages (from torch-geometric) (1.20.3)\n",
      "Requirement already satisfied: scikit-learn in c:\\users\\stariz.pk\\anaconda3\\lib\\site-packages (from torch-geometric) (0.24.2)\n",
      "Requirement already satisfied: tqdm in c:\\users\\stariz.pk\\anaconda3\\lib\\site-packages (from torch-geometric) (4.62.3)\n",
      "Requirement already satisfied: scipy in c:\\users\\stariz.pk\\anaconda3\\lib\\site-packages (from torch-geometric) (1.7.1)\n",
      "Requirement already satisfied: MarkupSafe>=0.23 in c:\\users\\stariz.pk\\anaconda3\\lib\\site-packages (from jinja2->torch-geometric) (1.1.1)\n",
      "Requirement already satisfied: charset-normalizer~=2.0.0 in c:\\users\\stariz.pk\\anaconda3\\lib\\site-packages (from requests->torch-geometric) (2.0.4)\n",
      "Requirement already satisfied: certifi>=2017.4.17 in c:\\users\\stariz.pk\\anaconda3\\lib\\site-packages (from requests->torch-geometric) (2021.10.8)\n",
      "Requirement already satisfied: idna<4,>=2.5 in c:\\users\\stariz.pk\\anaconda3\\lib\\site-packages (from requests->torch-geometric) (3.2)\n",
      "Requirement already satisfied: urllib3<1.27,>=1.21.1 in c:\\users\\stariz.pk\\anaconda3\\lib\\site-packages (from requests->torch-geometric) (1.26.7)\n",
      "Requirement already satisfied: threadpoolctl>=2.0.0 in c:\\users\\stariz.pk\\anaconda3\\lib\\site-packages (from scikit-learn->torch-geometric) (2.2.0)\n",
      "Requirement already satisfied: joblib>=0.11 in c:\\users\\stariz.pk\\anaconda3\\lib\\site-packages (from scikit-learn->torch-geometric) (1.1.0)\n",
      "Requirement already satisfied: colorama in c:\\users\\stariz.pk\\anaconda3\\lib\\site-packages (from tqdm->torch-geometric) (0.4.4)\n"
     ]
    }
   ],
   "source": [
    "import torch\n",
    "pytorch_version = f\"torch-{torch.__version__}.html\"\n",
    "!pip install --no-index torch-scatter -f https://pytorch-geometric.com/whl/$pytorch_version\n",
    "!pip install --no-index torch-sparse -f https://pytorch-geometric.com/whl/$pytorch_version\n",
    "!pip install --no-index torch-cluster -f https://pytorch-geometric.com/whl/$pytorch_version\n",
    "!pip install --no-index torch-spline-conv -f https://pytorch-geometric.com/whl/$pytorch_version\n",
    "!pip install torch-geometric"
   ]
  },
  {
   "cell_type": "code",
   "execution_count": 9,
   "id": "af641933",
   "metadata": {},
   "outputs": [
    {
     "name": "stdout",
     "output_type": "stream",
     "text": [
      "Looking in indexes: https://pypi.org/simple, https://download.pytorch.org/whl/cpu\n",
      "Collecting torch\n",
      "  Downloading https://download.pytorch.org/whl/cpu/torch-1.13.1%2Bcpu-cp39-cp39-win_amd64.whl (164.1 MB)\n"
     ]
    },
    {
     "name": "stderr",
     "output_type": "stream",
     "text": [
      "WARNING: Retrying (Retry(total=4, connect=None, read=None, redirect=None, status=None)) after connection broken by 'ReadTimeoutError(\"HTTPSConnectionPool(host='download.pytorch.org', port=443): Read timed out. (read timeout=15)\")': /whl/cpu/torch/\n",
      "ERROR: Exception:\n",
      "Traceback (most recent call last):\n",
      "  File \"C:\\Users\\STARIZ.PK\\anaconda3\\lib\\site-packages\\pip\\_vendor\\urllib3\\response.py\", line 438, in _error_catcher\n",
      "    yield\n",
      "  File \"C:\\Users\\STARIZ.PK\\anaconda3\\lib\\site-packages\\pip\\_vendor\\urllib3\\response.py\", line 519, in read\n",
      "    data = self._fp.read(amt) if not fp_closed else b\"\"\n",
      "  File \"C:\\Users\\STARIZ.PK\\anaconda3\\lib\\site-packages\\pip\\_vendor\\cachecontrol\\filewrapper.py\", line 62, in read\n",
      "    data = self.__fp.read(amt)\n",
      "  File \"C:\\Users\\STARIZ.PK\\anaconda3\\lib\\http\\client.py\", line 462, in read\n",
      "    n = self.readinto(b)\n",
      "  File \"C:\\Users\\STARIZ.PK\\anaconda3\\lib\\http\\client.py\", line 506, in readinto\n",
      "    n = self.fp.readinto(b)\n",
      "  File \"C:\\Users\\STARIZ.PK\\anaconda3\\lib\\socket.py\", line 704, in readinto\n",
      "    return self._sock.recv_into(b)\n",
      "  File \"C:\\Users\\STARIZ.PK\\anaconda3\\lib\\ssl.py\", line 1241, in recv_into\n",
      "    return self.read(nbytes, buffer)\n",
      "  File \"C:\\Users\\STARIZ.PK\\anaconda3\\lib\\ssl.py\", line 1099, in read\n",
      "    return self._sslobj.read(len, buffer)\n",
      "socket.timeout: The read operation timed out\n",
      "\n",
      "During handling of the above exception, another exception occurred:\n",
      "\n",
      "Traceback (most recent call last):\n",
      "  File \"C:\\Users\\STARIZ.PK\\anaconda3\\lib\\site-packages\\pip\\_internal\\cli\\base_command.py\", line 173, in _main\n",
      "    status = self.run(options, args)\n",
      "  File \"C:\\Users\\STARIZ.PK\\anaconda3\\lib\\site-packages\\pip\\_internal\\cli\\req_command.py\", line 203, in wrapper\n",
      "    return func(self, options, args)\n",
      "  File \"C:\\Users\\STARIZ.PK\\anaconda3\\lib\\site-packages\\pip\\_internal\\commands\\install.py\", line 315, in run\n",
      "    requirement_set = resolver.resolve(\n",
      "  File \"C:\\Users\\STARIZ.PK\\anaconda3\\lib\\site-packages\\pip\\_internal\\resolution\\resolvelib\\resolver.py\", line 94, in resolve\n",
      "    result = self._result = resolver.resolve(\n",
      "  File \"C:\\Users\\STARIZ.PK\\anaconda3\\lib\\site-packages\\pip\\_vendor\\resolvelib\\resolvers.py\", line 472, in resolve\n",
      "    state = resolution.resolve(requirements, max_rounds=max_rounds)\n",
      "  File \"C:\\Users\\STARIZ.PK\\anaconda3\\lib\\site-packages\\pip\\_vendor\\resolvelib\\resolvers.py\", line 341, in resolve\n",
      "    self._add_to_criteria(self.state.criteria, r, parent=None)\n",
      "  File \"C:\\Users\\STARIZ.PK\\anaconda3\\lib\\site-packages\\pip\\_vendor\\resolvelib\\resolvers.py\", line 172, in _add_to_criteria\n",
      "    if not criterion.candidates:\n",
      "  File \"C:\\Users\\STARIZ.PK\\anaconda3\\lib\\site-packages\\pip\\_vendor\\resolvelib\\structs.py\", line 151, in __bool__\n",
      "    return bool(self._sequence)\n",
      "  File \"C:\\Users\\STARIZ.PK\\anaconda3\\lib\\site-packages\\pip\\_internal\\resolution\\resolvelib\\found_candidates.py\", line 140, in __bool__\n",
      "    return any(self)\n",
      "  File \"C:\\Users\\STARIZ.PK\\anaconda3\\lib\\site-packages\\pip\\_internal\\resolution\\resolvelib\\found_candidates.py\", line 128, in <genexpr>\n",
      "    return (c for c in iterator if id(c) not in self._incompatible_ids)\n",
      "  File \"C:\\Users\\STARIZ.PK\\anaconda3\\lib\\site-packages\\pip\\_internal\\resolution\\resolvelib\\found_candidates.py\", line 32, in _iter_built\n",
      "    candidate = func()\n",
      "  File \"C:\\Users\\STARIZ.PK\\anaconda3\\lib\\site-packages\\pip\\_internal\\resolution\\resolvelib\\factory.py\", line 204, in _make_candidate_from_link\n",
      "    self._link_candidate_cache[link] = LinkCandidate(\n",
      "  File \"C:\\Users\\STARIZ.PK\\anaconda3\\lib\\site-packages\\pip\\_internal\\resolution\\resolvelib\\candidates.py\", line 295, in __init__\n",
      "    super().__init__(\n",
      "  File \"C:\\Users\\STARIZ.PK\\anaconda3\\lib\\site-packages\\pip\\_internal\\resolution\\resolvelib\\candidates.py\", line 156, in __init__\n",
      "    self.dist = self._prepare()\n",
      "  File \"C:\\Users\\STARIZ.PK\\anaconda3\\lib\\site-packages\\pip\\_internal\\resolution\\resolvelib\\candidates.py\", line 227, in _prepare\n",
      "    dist = self._prepare_distribution()\n",
      "  File \"C:\\Users\\STARIZ.PK\\anaconda3\\lib\\site-packages\\pip\\_internal\\resolution\\resolvelib\\candidates.py\", line 305, in _prepare_distribution\n",
      "    return self._factory.preparer.prepare_linked_requirement(\n",
      "  File \"C:\\Users\\STARIZ.PK\\anaconda3\\lib\\site-packages\\pip\\_internal\\operations\\prepare.py\", line 508, in prepare_linked_requirement\n",
      "    return self._prepare_linked_requirement(req, parallel_builds)\n",
      "  File \"C:\\Users\\STARIZ.PK\\anaconda3\\lib\\site-packages\\pip\\_internal\\operations\\prepare.py\", line 550, in _prepare_linked_requirement\n",
      "    local_file = unpack_url(\n",
      "  File \"C:\\Users\\STARIZ.PK\\anaconda3\\lib\\site-packages\\pip\\_internal\\operations\\prepare.py\", line 239, in unpack_url\n",
      "    file = get_http_url(\n",
      "  File \"C:\\Users\\STARIZ.PK\\anaconda3\\lib\\site-packages\\pip\\_internal\\operations\\prepare.py\", line 102, in get_http_url\n",
      "    from_path, content_type = download(link, temp_dir.path)\n",
      "  File \"C:\\Users\\STARIZ.PK\\anaconda3\\lib\\site-packages\\pip\\_internal\\network\\download.py\", line 145, in __call__\n",
      "    for chunk in chunks:\n",
      "  File \"C:\\Users\\STARIZ.PK\\anaconda3\\lib\\site-packages\\pip\\_internal\\cli\\progress_bars.py\", line 144, in iter\n",
      "    for x in it:\n",
      "  File \"C:\\Users\\STARIZ.PK\\anaconda3\\lib\\site-packages\\pip\\_internal\\network\\utils.py\", line 63, in response_chunks\n",
      "    for chunk in response.raw.stream(\n",
      "  File \"C:\\Users\\STARIZ.PK\\anaconda3\\lib\\site-packages\\pip\\_vendor\\urllib3\\response.py\", line 576, in stream\n",
      "    data = self.read(amt=amt, decode_content=decode_content)\n",
      "  File \"C:\\Users\\STARIZ.PK\\anaconda3\\lib\\site-packages\\pip\\_vendor\\urllib3\\response.py\", line 541, in read\n",
      "    raise IncompleteRead(self._fp_bytes_read, self.length_remaining)\n",
      "  File \"C:\\Users\\STARIZ.PK\\anaconda3\\lib\\contextlib.py\", line 137, in __exit__\n",
      "    self.gen.throw(typ, value, traceback)\n",
      "  File \"C:\\Users\\STARIZ.PK\\anaconda3\\lib\\site-packages\\pip\\_vendor\\urllib3\\response.py\", line 443, in _error_catcher\n",
      "    raise ReadTimeoutError(self._pool, None, \"Read timed out.\")\n",
      "pip._vendor.urllib3.exceptions.ReadTimeoutError: HTTPSConnectionPool(host='download.pytorch.org', port=443): Read timed out.\n"
     ]
    },
    {
     "name": "stdout",
     "output_type": "stream",
     "text": [
      "Looking in links: https://data.pyg.org/whl/torch-1.12.0+cpu.html\n",
      "Requirement already satisfied: torch-scatter in c:\\users\\stariz.pk\\anaconda3\\lib\\site-packages (2.1.0+pt112cpu)\n",
      "Collecting torch-sparse\n",
      "  Downloading https://data.pyg.org/whl/torch-1.12.0%2Bcpu/torch_sparse-0.6.16%2Bpt112cpu-cp39-cp39-win_amd64.whl (743 kB)\n"
     ]
    },
    {
     "name": "stderr",
     "output_type": "stream",
     "text": [
      "ERROR: Exception:\n",
      "Traceback (most recent call last):\n",
      "  File \"C:\\Users\\STARIZ.PK\\anaconda3\\lib\\site-packages\\pip\\_vendor\\urllib3\\response.py\", line 438, in _error_catcher\n",
      "    yield\n",
      "  File \"C:\\Users\\STARIZ.PK\\anaconda3\\lib\\site-packages\\pip\\_vendor\\urllib3\\response.py\", line 519, in read\n",
      "    data = self._fp.read(amt) if not fp_closed else b\"\"\n",
      "  File \"C:\\Users\\STARIZ.PK\\anaconda3\\lib\\site-packages\\pip\\_vendor\\cachecontrol\\filewrapper.py\", line 62, in read\n",
      "    data = self.__fp.read(amt)\n",
      "  File \"C:\\Users\\STARIZ.PK\\anaconda3\\lib\\http\\client.py\", line 462, in read\n",
      "    n = self.readinto(b)\n",
      "  File \"C:\\Users\\STARIZ.PK\\anaconda3\\lib\\http\\client.py\", line 506, in readinto\n",
      "    n = self.fp.readinto(b)\n",
      "  File \"C:\\Users\\STARIZ.PK\\anaconda3\\lib\\socket.py\", line 704, in readinto\n",
      "    return self._sock.recv_into(b)\n",
      "  File \"C:\\Users\\STARIZ.PK\\anaconda3\\lib\\ssl.py\", line 1241, in recv_into\n",
      "    return self.read(nbytes, buffer)\n",
      "  File \"C:\\Users\\STARIZ.PK\\anaconda3\\lib\\ssl.py\", line 1099, in read\n",
      "    return self._sslobj.read(len, buffer)\n",
      "socket.timeout: The read operation timed out\n",
      "\n",
      "During handling of the above exception, another exception occurred:\n",
      "\n",
      "Traceback (most recent call last):\n",
      "  File \"C:\\Users\\STARIZ.PK\\anaconda3\\lib\\site-packages\\pip\\_internal\\cli\\base_command.py\", line 173, in _main\n",
      "    status = self.run(options, args)\n",
      "  File \"C:\\Users\\STARIZ.PK\\anaconda3\\lib\\site-packages\\pip\\_internal\\cli\\req_command.py\", line 203, in wrapper\n",
      "    return func(self, options, args)\n",
      "  File \"C:\\Users\\STARIZ.PK\\anaconda3\\lib\\site-packages\\pip\\_internal\\commands\\install.py\", line 315, in run\n",
      "    requirement_set = resolver.resolve(\n",
      "  File \"C:\\Users\\STARIZ.PK\\anaconda3\\lib\\site-packages\\pip\\_internal\\resolution\\resolvelib\\resolver.py\", line 94, in resolve\n",
      "    result = self._result = resolver.resolve(\n",
      "  File \"C:\\Users\\STARIZ.PK\\anaconda3\\lib\\site-packages\\pip\\_vendor\\resolvelib\\resolvers.py\", line 472, in resolve\n",
      "    state = resolution.resolve(requirements, max_rounds=max_rounds)\n",
      "  File \"C:\\Users\\STARIZ.PK\\anaconda3\\lib\\site-packages\\pip\\_vendor\\resolvelib\\resolvers.py\", line 341, in resolve\n",
      "    self._add_to_criteria(self.state.criteria, r, parent=None)\n",
      "  File \"C:\\Users\\STARIZ.PK\\anaconda3\\lib\\site-packages\\pip\\_vendor\\resolvelib\\resolvers.py\", line 172, in _add_to_criteria\n",
      "    if not criterion.candidates:\n",
      "  File \"C:\\Users\\STARIZ.PK\\anaconda3\\lib\\site-packages\\pip\\_vendor\\resolvelib\\structs.py\", line 151, in __bool__\n",
      "    return bool(self._sequence)\n",
      "  File \"C:\\Users\\STARIZ.PK\\anaconda3\\lib\\site-packages\\pip\\_internal\\resolution\\resolvelib\\found_candidates.py\", line 140, in __bool__\n",
      "    return any(self)\n",
      "  File \"C:\\Users\\STARIZ.PK\\anaconda3\\lib\\site-packages\\pip\\_internal\\resolution\\resolvelib\\found_candidates.py\", line 128, in <genexpr>\n",
      "    return (c for c in iterator if id(c) not in self._incompatible_ids)\n",
      "  File \"C:\\Users\\STARIZ.PK\\anaconda3\\lib\\site-packages\\pip\\_internal\\resolution\\resolvelib\\found_candidates.py\", line 32, in _iter_built\n",
      "    candidate = func()\n",
      "  File \"C:\\Users\\STARIZ.PK\\anaconda3\\lib\\site-packages\\pip\\_internal\\resolution\\resolvelib\\factory.py\", line 204, in _make_candidate_from_link\n",
      "    self._link_candidate_cache[link] = LinkCandidate(\n",
      "  File \"C:\\Users\\STARIZ.PK\\anaconda3\\lib\\site-packages\\pip\\_internal\\resolution\\resolvelib\\candidates.py\", line 295, in __init__\n",
      "    super().__init__(\n",
      "  File \"C:\\Users\\STARIZ.PK\\anaconda3\\lib\\site-packages\\pip\\_internal\\resolution\\resolvelib\\candidates.py\", line 156, in __init__\n",
      "    self.dist = self._prepare()\n",
      "  File \"C:\\Users\\STARIZ.PK\\anaconda3\\lib\\site-packages\\pip\\_internal\\resolution\\resolvelib\\candidates.py\", line 227, in _prepare\n",
      "    dist = self._prepare_distribution()\n",
      "  File \"C:\\Users\\STARIZ.PK\\anaconda3\\lib\\site-packages\\pip\\_internal\\resolution\\resolvelib\\candidates.py\", line 305, in _prepare_distribution\n",
      "    return self._factory.preparer.prepare_linked_requirement(\n",
      "  File \"C:\\Users\\STARIZ.PK\\anaconda3\\lib\\site-packages\\pip\\_internal\\operations\\prepare.py\", line 508, in prepare_linked_requirement\n",
      "    return self._prepare_linked_requirement(req, parallel_builds)\n",
      "  File \"C:\\Users\\STARIZ.PK\\anaconda3\\lib\\site-packages\\pip\\_internal\\operations\\prepare.py\", line 550, in _prepare_linked_requirement\n",
      "    local_file = unpack_url(\n",
      "  File \"C:\\Users\\STARIZ.PK\\anaconda3\\lib\\site-packages\\pip\\_internal\\operations\\prepare.py\", line 239, in unpack_url\n",
      "    file = get_http_url(\n",
      "  File \"C:\\Users\\STARIZ.PK\\anaconda3\\lib\\site-packages\\pip\\_internal\\operations\\prepare.py\", line 102, in get_http_url\n",
      "    from_path, content_type = download(link, temp_dir.path)\n",
      "  File \"C:\\Users\\STARIZ.PK\\anaconda3\\lib\\site-packages\\pip\\_internal\\network\\download.py\", line 145, in __call__\n",
      "    for chunk in chunks:\n",
      "  File \"C:\\Users\\STARIZ.PK\\anaconda3\\lib\\site-packages\\pip\\_internal\\cli\\progress_bars.py\", line 144, in iter\n",
      "    for x in it:\n",
      "  File \"C:\\Users\\STARIZ.PK\\anaconda3\\lib\\site-packages\\pip\\_internal\\network\\utils.py\", line 63, in response_chunks\n",
      "    for chunk in response.raw.stream(\n",
      "  File \"C:\\Users\\STARIZ.PK\\anaconda3\\lib\\site-packages\\pip\\_vendor\\urllib3\\response.py\", line 576, in stream\n",
      "    data = self.read(amt=amt, decode_content=decode_content)\n",
      "  File \"C:\\Users\\STARIZ.PK\\anaconda3\\lib\\site-packages\\pip\\_vendor\\urllib3\\response.py\", line 541, in read\n",
      "    raise IncompleteRead(self._fp_bytes_read, self.length_remaining)\n",
      "  File \"C:\\Users\\STARIZ.PK\\anaconda3\\lib\\contextlib.py\", line 137, in __exit__\n",
      "    self.gen.throw(typ, value, traceback)\n",
      "  File \"C:\\Users\\STARIZ.PK\\anaconda3\\lib\\site-packages\\pip\\_vendor\\urllib3\\response.py\", line 443, in _error_catcher\n",
      "    raise ReadTimeoutError(self._pool, None, \"Read timed out.\")\n",
      "pip._vendor.urllib3.exceptions.ReadTimeoutError: HTTPSConnectionPool(host='data.pyg.org', port=443): Read timed out.\n"
     ]
    }
   ],
   "source": [
    "!pip install torch torchvision torchaudio --extra-index-url https://download.pytorch.org/whl/cpu\n",
    "!pip install torch-scatter torch-sparse torch-cluster torch-spline-conv torch-geometric -f https://data.pyg.org/whl/torch-1.12.0+cpu.html"
   ]
  },
  {
   "cell_type": "code",
   "execution_count": 10,
   "id": "f60fba9a",
   "metadata": {},
   "outputs": [
    {
     "ename": "ModuleNotFoundError",
     "evalue": "No module named 'torch_sparse'",
     "output_type": "error",
     "traceback": [
      "\u001b[1;31m---------------------------------------------------------------------------\u001b[0m",
      "\u001b[1;31mModuleNotFoundError\u001b[0m                       Traceback (most recent call last)",
      "\u001b[1;32m~\\AppData\\Local\\Temp/ipykernel_15632/2906765395.py\u001b[0m in \u001b[0;36m<module>\u001b[1;34m\u001b[0m\n\u001b[0;32m      4\u001b[0m \u001b[1;32mimport\u001b[0m \u001b[0mnetworkx\u001b[0m \u001b[1;32mas\u001b[0m \u001b[0mnx\u001b[0m\u001b[1;33m\u001b[0m\u001b[1;33m\u001b[0m\u001b[0m\n\u001b[0;32m      5\u001b[0m \u001b[1;32mimport\u001b[0m \u001b[0mcopy\u001b[0m\u001b[1;33m\u001b[0m\u001b[1;33m\u001b[0m\u001b[0m\n\u001b[1;32m----> 6\u001b[1;33m \u001b[1;32mfrom\u001b[0m \u001b[0mtorch_geometric\u001b[0m\u001b[1;33m.\u001b[0m\u001b[0mutils\u001b[0m \u001b[1;32mimport\u001b[0m \u001b[0mdegree\u001b[0m\u001b[1;33m,\u001b[0m\u001b[0mstructured_negative_sampling\u001b[0m\u001b[1;33m\u001b[0m\u001b[1;33m\u001b[0m\u001b[0m\n\u001b[0m\u001b[0;32m      7\u001b[0m \u001b[1;32mfrom\u001b[0m \u001b[0mtorch_geometric\u001b[0m\u001b[1;33m.\u001b[0m\u001b[0mnn\u001b[0m\u001b[1;33m.\u001b[0m\u001b[0mconv\u001b[0m\u001b[1;33m.\u001b[0m\u001b[0mgcn_conv\u001b[0m \u001b[1;32mimport\u001b[0m \u001b[0mgcn_norm\u001b[0m\u001b[1;33m\u001b[0m\u001b[1;33m\u001b[0m\u001b[0m\n\u001b[0;32m      8\u001b[0m \u001b[1;32mfrom\u001b[0m \u001b[0mtorch_geometric\u001b[0m\u001b[1;33m.\u001b[0m\u001b[0mnn\u001b[0m\u001b[1;33m.\u001b[0m\u001b[0mconv\u001b[0m \u001b[1;32mimport\u001b[0m \u001b[0mMessagePassing\u001b[0m\u001b[1;33m\u001b[0m\u001b[1;33m\u001b[0m\u001b[0m\n",
      "\u001b[1;32m~\\anaconda3\\lib\\site-packages\\torch_geometric\\__init__.py\u001b[0m in \u001b[0;36m<module>\u001b[1;34m\u001b[0m\n\u001b[0;32m      2\u001b[0m \u001b[1;32mfrom\u001b[0m \u001b[0mimportlib\u001b[0m \u001b[1;32mimport\u001b[0m \u001b[0mimport_module\u001b[0m\u001b[1;33m\u001b[0m\u001b[1;33m\u001b[0m\u001b[0m\n\u001b[0;32m      3\u001b[0m \u001b[1;33m\u001b[0m\u001b[0m\n\u001b[1;32m----> 4\u001b[1;33m \u001b[1;32mimport\u001b[0m \u001b[0mtorch_geometric\u001b[0m\u001b[1;33m.\u001b[0m\u001b[0mdata\u001b[0m\u001b[1;33m\u001b[0m\u001b[1;33m\u001b[0m\u001b[0m\n\u001b[0m\u001b[0;32m      5\u001b[0m \u001b[1;32mimport\u001b[0m \u001b[0mtorch_geometric\u001b[0m\u001b[1;33m.\u001b[0m\u001b[0mloader\u001b[0m\u001b[1;33m\u001b[0m\u001b[1;33m\u001b[0m\u001b[0m\n\u001b[0;32m      6\u001b[0m \u001b[1;32mimport\u001b[0m \u001b[0mtorch_geometric\u001b[0m\u001b[1;33m.\u001b[0m\u001b[0mtransforms\u001b[0m\u001b[1;33m\u001b[0m\u001b[1;33m\u001b[0m\u001b[0m\n",
      "\u001b[1;32m~\\anaconda3\\lib\\site-packages\\torch_geometric\\data\\__init__.py\u001b[0m in \u001b[0;36m<module>\u001b[1;34m\u001b[0m\n\u001b[1;32m----> 1\u001b[1;33m \u001b[1;32mfrom\u001b[0m \u001b[1;33m.\u001b[0m\u001b[0mdata\u001b[0m \u001b[1;32mimport\u001b[0m \u001b[0mData\u001b[0m\u001b[1;33m\u001b[0m\u001b[1;33m\u001b[0m\u001b[0m\n\u001b[0m\u001b[0;32m      2\u001b[0m \u001b[1;32mfrom\u001b[0m \u001b[1;33m.\u001b[0m\u001b[0mhetero_data\u001b[0m \u001b[1;32mimport\u001b[0m \u001b[0mHeteroData\u001b[0m\u001b[1;33m\u001b[0m\u001b[1;33m\u001b[0m\u001b[0m\n\u001b[0;32m      3\u001b[0m \u001b[1;32mfrom\u001b[0m \u001b[1;33m.\u001b[0m\u001b[0mtemporal\u001b[0m \u001b[1;32mimport\u001b[0m \u001b[0mTemporalData\u001b[0m\u001b[1;33m\u001b[0m\u001b[1;33m\u001b[0m\u001b[0m\n\u001b[0;32m      4\u001b[0m \u001b[1;32mfrom\u001b[0m \u001b[1;33m.\u001b[0m\u001b[0mbatch\u001b[0m \u001b[1;32mimport\u001b[0m \u001b[0mBatch\u001b[0m\u001b[1;33m\u001b[0m\u001b[1;33m\u001b[0m\u001b[0m\n\u001b[0;32m      5\u001b[0m \u001b[1;32mfrom\u001b[0m \u001b[1;33m.\u001b[0m\u001b[0mdataset\u001b[0m \u001b[1;32mimport\u001b[0m \u001b[0mDataset\u001b[0m\u001b[1;33m\u001b[0m\u001b[1;33m\u001b[0m\u001b[0m\n",
      "\u001b[1;32m~\\anaconda3\\lib\\site-packages\\torch_geometric\\data\\data.py\u001b[0m in \u001b[0;36m<module>\u001b[1;34m\u001b[0m\n\u001b[0;32m     18\u001b[0m \u001b[1;32mimport\u001b[0m \u001b[0mtorch\u001b[0m\u001b[1;33m\u001b[0m\u001b[1;33m\u001b[0m\u001b[0m\n\u001b[0;32m     19\u001b[0m \u001b[1;32mfrom\u001b[0m \u001b[0mtorch\u001b[0m \u001b[1;32mimport\u001b[0m \u001b[0mTensor\u001b[0m\u001b[1;33m\u001b[0m\u001b[1;33m\u001b[0m\u001b[0m\n\u001b[1;32m---> 20\u001b[1;33m \u001b[1;32mfrom\u001b[0m \u001b[0mtorch_sparse\u001b[0m \u001b[1;32mimport\u001b[0m \u001b[0mSparseTensor\u001b[0m\u001b[1;33m\u001b[0m\u001b[1;33m\u001b[0m\u001b[0m\n\u001b[0m\u001b[0;32m     21\u001b[0m \u001b[1;33m\u001b[0m\u001b[0m\n\u001b[0;32m     22\u001b[0m from torch_geometric.data.feature_store import (\n",
      "\u001b[1;31mModuleNotFoundError\u001b[0m: No module named 'torch_sparse'"
     ]
    }
   ],
   "source": [
    "import numpy as np\n",
    "from scipy.linalg import sqrtm \n",
    "from scipy.special import softmax\n",
    "import networkx as nx\n",
    "import copy\n",
    "from torch_geometric.utils import degree,structured_negative_sampling\n",
    "from torch_geometric.nn.conv.gcn_conv import gcn_norm\n",
    "from torch_geometric.nn.conv import MessagePassing\n",
    "from torch_geometric.typing import Adj\n",
    "import torch\n",
    "from torch import nn,optim,Tensor\n",
    "from torch_sparse import SparseTensor,matmul\n",
    "from sklearn.model_selection import train_test_split\n",
    "from sklearn import model_selection, metrics,preprocessing\n",
    "\n",
    "\n",
    "import random\n",
    "from tqdm.notebook import tqdm\n",
    "import pandas as pd\n",
    "import pickle\n",
    "import networkx as nx\n",
    "import pickle\n",
    "import os\n",
    "import torch\n",
    "import pandas as pd\n"
   ]
  },
  {
   "cell_type": "code",
   "execution_count": null,
   "id": "b3bedffc",
   "metadata": {},
   "outputs": [],
   "source": []
  }
 ],
 "metadata": {
  "kernelspec": {
   "display_name": "Python 3 (ipykernel)",
   "language": "python",
   "name": "python3"
  },
  "language_info": {
   "codemirror_mode": {
    "name": "ipython",
    "version": 3
   },
   "file_extension": ".py",
   "mimetype": "text/x-python",
   "name": "python",
   "nbconvert_exporter": "python",
   "pygments_lexer": "ipython3",
   "version": "3.9.7"
  }
 },
 "nbformat": 4,
 "nbformat_minor": 5
}
